<?xml version="1.0" ?>
<!-- =================================================================================== -->
<!-- |    This document was autogenerated by xacro from /home/mksneo/mks_ws/src/mks_description/urdf/eve.urdf.xacro | -->
<!-- |    EDITING THIS FILE BY HAND IS NOT RECOMMENDED                                 | -->
<!-- =================================================================================== -->
<robot name="eve">
  <link name="root"/>
  <link name="chassis">
    <visual>
      <origin rpy="1.5707963267948966 0 0" xyz="0 0 0.0"/>
      <geometry>
        <mesh filename="/home/mksneo/mks_ws/src/mks_description/meshes/chassis.stl" scale="0.001 0.001 0.001"/>
      </geometry>
    </visual>
    <collision>
      <origin rpy="1.5707963267948966 0 0" xyz="0 0 0"/>
      <geometry>
        <mesh filename="/home/mksneo/mks_ws/src/mks_description/meshes/simplified_meshes/chassis_simp.stl" scale="0.001 0.001 0.001"/>
      </geometry>
    </collision>
    <inertial>
      <origin rpy="0 0 0" xyz="0 0 0"/>
      <mass value="5.0"/>
      <inertia ixx="0.013" ixy="0" ixz="0" iyy="0.009" iyz="0" izz="0.005"/>
    </inertial>
  </link>
  <joint name="base_joint" type="fixed">
    <parent link="root"/>
    <child link="chassis"/>
    <origin rpy="0 0 0" xyz="0 0 0"/>
  </joint>
  <link name="front_left_leg">
    <visual>
      <origin rpy="1.5707963267948966 0 0" xyz="-0.247 0.058093 -0.025691"/>
      <geometry>
        <mesh filename="/home/mksneo/mks_ws/src/mks_description/meshes/front_left_leg.stl" scale="0.001 0.001 0.001"/>
      </geometry>
    </visual>
    <collision>
      <origin rpy="1.5707963267948966 0 0" xyz="-0.247 0.058093 -0.025691"/>
      <geometry>
        <mesh filename="/home/mksneo/mks_ws/src/mks_description/meshes/simplified_meshes/front_left_leg_simp.stl" scale="0.001 0.001 0.001"/>
      </geometry>
    </collision>
    <inertial>
      <origin rpy="0 0 0" xyz="0 0 0"/>
      <mass value="1.5"/>
      <inertia ixx="0.008" ixy="0" ixz="0" iyy="0.008" iyz="0" izz="0.0009"/>
    </inertial>
  </link>
  <link name="front_right_leg">
    <visual>
      <origin rpy="1.5707963267948966 0 0" xyz="0.247 0.058093 -0.025691"/>
      <geometry>
        <mesh filename="/home/mksneo/mks_ws/src/mks_description/meshes/front_right_leg.stl" scale="0.001 0.001 0.001"/>
      </geometry>
    </visual>
    <collision>
      <origin rpy="1.5707963267948966 0 0" xyz="0.247 0.058093 -0.025691"/>
      <geometry>
        <mesh filename="/home/mksneo/mks_ws/src/mks_description/meshes/simplified_meshes/front_right_leg_simp.stl" scale="0.001 0.001 0.001"/>
      </geometry>
    </collision>
    <inertial>
      <origin rpy="0 0 0" xyz="0 0 0"/>
      <mass value="1.5"/>
      <inertia ixx="0.008" ixy="0" ixz="0" iyy="0.008" iyz="0" izz="0.0009"/>
    </inertial>
  </link>
  <link name="back_left_leg">
    <visual>
      <origin rpy="1.5707963267948966 0 0" xyz="-0.247 -0.058093 -0.025691"/>
      <geometry>
        <mesh filename="/home/mksneo/mks_ws/src/mks_description/meshes/back_left_leg.stl" scale="0.001 0.001 0.001"/>
      </geometry>
    </visual>
    <collision>
      <origin rpy="1.5707963267948966 0 0" xyz="-0.247 -0.058093 -0.025691"/>
      <geometry>
        <mesh filename="/home/mksneo/mks_ws/src/mks_description/meshes/simplified_meshes/back_left_leg_simp.stl" scale="0.001 0.001 0.001"/>
      </geometry>
    </collision>
    <inertial>
      <origin rpy="0 0 0" xyz="0 0 0"/>
      <mass value="1.5"/>
      <inertia ixx="0.008" ixy="0" ixz="0" iyy="0.008" iyz="0" izz="0.0009"/>
    </inertial>
  </link>
  <link name="back_right_leg">
    <visual>
      <origin rpy="1.5707963267948966 0 0" xyz="0.247 -0.058093 -0.025691"/>
      <geometry>
        <mesh filename="/home/mksneo/mks_ws/src/mks_description/meshes/back_right_leg.stl" scale="0.001 0.001 0.001"/>
      </geometry>
    </visual>
    <collision>
      <origin rpy="1.5707963267948966 0 0" xyz="0.247 -0.058093 -0.025691"/>
      <geometry>
        <mesh filename="/home/mksneo/mks_ws/src/mks_description/meshes/simplified_meshes/back_right_leg_simp.stl" scale="0.001 0.001 0.001"/>
      </geometry>
    </collision>
    <inertial>
      <origin rpy="0 0 0" xyz="0 0 0"/>
      <mass value="1.5"/>
      <inertia ixx="0.008" ixy="0" ixz="0" iyy="0.008" iyz="0" izz="0.0009"/>
    </inertial>
  </link>
  <link name="front_left_wheel">
    <visual>
      <origin rpy="1.5707963267948966 0 0" xyz="-0.3395 0.445997 -0.016173"/>
      <geometry>
        <mesh filename="/home/mksneo/mks_ws/src/mks_description/meshes/front_left_wheel.stl" scale="0.001 0.001 0.001"/>
      </geometry>
    </visual>
    <collision>
      <origin rpy="1.5707963267948966 0 0" xyz="-0.3395 0.445997 -0.016173"/>
      <geometry>
        <mesh filename="/home/mksneo/mks_ws/src/mks_description/meshes/simplified_meshes/front_left_wheel_simp.stl" scale="0.001 0.001 0.001"/>
      </geometry>
    </collision>
    <inertial>
      <origin rpy="0 0 0" xyz="0 0 0"/>
      <mass value="0.8"/>
      <inertia ixx="0.001" ixy="0" ixz="0" iyy="0.0009" iyz="0" izz="0.0009"/>
    </inertial>
  </link>
  <link name="front_right_wheel">
    <visual>
      <origin rpy="1.5707963267948966 0 0" xyz="0.3395 0.445997 -0.016173"/>
      <geometry>
        <mesh filename="/home/mksneo/mks_ws/src/mks_description/meshes/front_right_wheel.stl" scale="0.001 0.001 0.001"/>
      </geometry>
    </visual>
    <collision>
      <origin rpy="1.5707963267948966 0 0" xyz="0.3395 0.445997 -0.016173"/>
      <geometry>
        <mesh filename="/home/mksneo/mks_ws/src/mks_description/meshes/simplified_meshes/front_right_wheel_simp.stl" scale="0.001 0.001 0.001"/>
      </geometry>
    </collision>
    <inertial>
      <origin rpy="0 0 0" xyz="0 0 0"/>
      <mass value="0.8"/>
      <inertia ixx="0.001" ixy="0" ixz="0" iyy="0.0009" iyz="0" izz="0.0009"/>
    </inertial>
  </link>
  <link name="back_left_wheel">
    <visual>
      <origin rpy="1.5707963267948966 0 0" xyz="-0.3395 0.445997 -0.016173"/>
      <geometry>
        <mesh filename="/home/mksneo/mks_ws/src/mks_description/meshes/back_left_wheel.stl" scale="0.001 0.001 0.001"/>
      </geometry>
    </visual>
    <collision>
      <origin rpy="1.5707963267948966 0 0" xyz="-0.3395 0.445997 -0.016173"/>
      <geometry>
        <mesh filename="/home/mksneo/mks_ws/src/mks_description/meshes/simplified_meshes/back_left_wheel_simp.stl" scale="0.001 0.001 0.001"/>
      </geometry>
    </collision>
    <inertial>
      <origin rpy="0 0 0" xyz="0 0 0"/>
      <mass value="0.8"/>
      <inertia ixx="0.001" ixy="0" ixz="0" iyy="0.0009" iyz="0" izz="0.0009"/>
    </inertial>
  </link>
  <link name="back_right_wheel">
    <visual>
      <origin rpy="1.5707963267948966 0 0" xyz="0.3395 0.445997 -0.016173"/>
      <geometry>
        <mesh filename="/home/mksneo/mks_ws/src/mks_description/meshes/back_right_wheel.stl" scale="0.001 0.001 0.001"/>
      </geometry>
    </visual>
    <collision>
      <origin rpy="1.5707963267948966 0 0" xyz="0.3395 0.445997 -0.016173"/>
      <geometry>
        <mesh filename="/home/mksneo/mks_ws/src/mks_description/meshes/simplified_meshes/back_right_wheel_simp.stl" scale="0.001 0.001 0.001"/>
      </geometry>
    </collision>
    <inertial>
      <origin rpy="0 0 0" xyz="0 0 0"/>
      <mass value="0.8"/>
      <inertia ixx="0.001" ixy="0" ixz="0" iyy="0.0009" iyz="0" izz="0.0009"/>
    </inertial>
  </link>
  <joint name="front_left_leg_to_chassis" type="revolute">
    <parent link="chassis"/>
    <child link="front_left_leg"/>
    <origin rpy="0 0 0" xyz="0.247 -0.058093 +0.025691"/>
    <axis xyz="1 0 0"/>
    <limit effort="5.0" lower="0" upper="1.0471975511965976" velocity="1.0"/>
  </joint>
  <joint name="front_right_leg_to_chassis" type="revolute">
    <parent link="chassis"/>
    <child link="front_right_leg"/>
    <origin rpy="0 0 0" xyz="-0.247 -0.058093 +0.025691"/>
    <axis xyz="1 0 0"/>
    <limit effort="5.0" lower="0" upper="1.0471975511965976" velocity="1.0"/>
  </joint>
  <joint name="back_left_leg_to_chassis" type="revolute">
    <parent link="chassis"/>
    <child link="back_left_leg"/>
    <origin rpy="0 0 0" xyz="0.247 0.058093 +0.025691"/>
    <axis xyz="1 0 0"/>
    <limit effort="5.0" lower="-1.0471975511965976" upper="0" velocity="1.0"/>
  </joint>
  <joint name="back_right_leg_to_chassis" type="revolute">
    <parent link="chassis"/>
    <child link="back_right_leg"/>
    <origin rpy="0 0 0" xyz="-0.247 0.058093 +0.025691"/>
    <axis xyz="1 0 0"/>
    <limit effort="5.0" lower="-1.0471975511965976" upper="0" velocity="1.0"/>
  </joint>
  <joint name="front_left_wheel_to_leg" type="continuous">
    <parent link="front_left_leg"/>
    <child link="front_left_wheel"/>
    <origin rpy="0 0 0" xyz="0.0925 -0.387904 -0.009518"/>
    <axis xyz="1 0 0"/>
  </joint>
  <joint name="front_right_wheel_to_leg" type="continuous">
    <parent link="front_right_leg"/>
    <child link="front_right_wheel"/>
    <origin rpy="0 0 0" xyz="-0.0925 -0.387904 -0.009518"/>
    <axis xyz="1 0 0"/>
  </joint>
  <joint name="back_left_wheel_to_leg" type="continuous">
    <parent link="back_left_leg"/>
    <child link="back_left_wheel"/>
    <origin rpy="0 0 0" xyz="0.0925 0.387904 -0.009518"/>
    <axis xyz="1 0 0"/>
  </joint>
  <joint name="back_right_wheel_to_leg" type="continuous">
    <parent link="back_right_leg"/>
    <child link="back_right_wheel"/>
    <origin rpy="0 0 0" xyz="-0.0925 0.387904 -0.009518"/>
    <axis xyz="1 0 0"/>
  </joint>
</robot>